Workbook

Sheet Table 6#
A1: CITY OF SCHERTZ, TEXAS
A3: TOTAL WATER AND SEWER CONSUMPTION AND RATES
A5: LAST TEN FISCAL YEARS
A9: Fiscal
A10: Year | C10: Total Water & | E10: Water & | G10: Water & Sewer
A11: Ended | C11: Sewer Consumption | E11: Sewer | G11: Initial Rate Per
A12: September 30, | C12: (In Gallons) | E12: Base Rate | G12: 1,000 Gallons
A13: 2024 | C13: 2425608700 | E13: 42.35 | G13: 8.41 | J13: Residential Est SWR | K13: 3085775575
A14: 2023 | C14: 2363742000 | E14: 40.85 | G14: 8.13
A15: 2022 | C15: 1700418300 | E15: 39.04 | G15: 7.79
A16: 2021 | C16: 1629336300 | E16: 38.15 | G16: 6.97
A17: 2020 | C17: 1982664200 | E17: 38.15 | G17: 6.97
A18: 2019 | C18: 1622930500 | E18: 37.15 | G18: 6.84
A19: 2018 | C19: 1583312400 | E19: 35.61 | G19: 6.53
A20: 2017 | C20: 1583462300 | E20: 34.35 | G20: 6.21
A21: 2016 | C21: 1509250000 | E21: 30.11 | G21: 5.73
A22: 2015 | C22: 1472948300 | E22: 26.54 | G22: 5.43
A23: 2014 | C23: 1543351600 | E23: 24.38 | G23: 5.17
A24: 2013 | C24: 1550039700 | E24: 22.69 | G24: 4.84
A25: 2012 | C25: 1604952300 | E25: 22.69 | G25: 4.84
A28: *Source: Schertz Utility System

Sheet Table 7
A1: CITY OF SCHERTZ, TEXAS
A3: PRINCIPAL WATER AND SEWER CONSUMERS
A5: LAST TEN FISCAL YEARS
C9: 2024 | I9: 2015 | T9: 2023 | AB9: 2021 | AH9: 2012
A10: TAXPAYERS | C10: Total Water Consumption (In Gallons) | E10: Rank | G10: Percentage of Total City Water Consumption | I10: Total Water Consumption (In Gallons) | K10: Rank | M10: Percentage of Total City Water Consumption | V10: 1 | AA10: City of Selma | AB10: 34375405 | AC10: =AB10*100 -> 3437540500 | AE10: SYSCO | AF10: 23384500 | AH10: Lions Fut Ball Club | AI10: 251410 | AJ10: =AI10*100 -> 25141000
R11: Scenic Hills Lawn Care | T11: =8201400+7557400 -> 15758800 | V11: 2 | AA11: City of Selma | AB11: 1064616 | AC11: =AB11*100 -> 106461600 | AE11: Caterpillar | AF11: 20741100 | AH11: Sysco | AI11: 101023 | AJ11: =AI11*100 -> 10102300
A12: City of Cibolo | C12: =155968*100 -> 15596800 | E12: 1 | G12: =C12/$C$33 -> 0.0064300561 | R12: WHC Schertz Apts, LLC | T12: 14287200 | V12: 3 | AA12: Caterpillar | AB12: 172401 | AC12: =AB12*100 -> 17240100 | AE12: Sycamore Creek Apartments | AF12: 10869700 | AH12: Beck Readymix Concrete | AI12: 85676 | AJ12: =AI12*100 -> 8567600
A13: WHC Schertz Apts, LLC | C13: =140166*100 -> 14016600 | E13: 2 | G13: =C14/$C$33 -> 0.004684185 | R13: City of Cibolo | T13: 12822500 | V13: 4 | AA13: City of Cibolo | AB13: 148932 | AC13: =AB13*100 -> 14893200 | AE13: Waterford Ridge Apartments | AF13: 9537700 | AH13: Pecan Grove TXLLC | AI13: 67662 | AJ13: =AI13*100 -> 6766200
A14: Ranger Excavating | C14: =113620*100 -> 11362000 | E14: 3 | G14: =C15/$C$33 -> 0.0044775977 | R14: Crossvine Master Community | T14: 12051600 | V14: 5 | AA14: Crossvine Master Community | AB14: 125061 | AC14: =AB14*100 -> 12506100 | AE14: Beck Readymix | AF14: 9366900 | AH14: IPT San Antonio Logistics | AI14: 64474 | AJ14: =AI14*100 -> 6447400
A15: Crossvine Master Community | C15: =108609*100 -> 10860900 | E15: 4 | G15: =C16/$C$33 -> 0.003866782 | R15: Pecan Grove | T15: 9768200 | V15: 6 | AA15: Pecan Grove TXLLC | AB15: 110736 | AC15: =AB15*100 -> 11073600 | AE15: Ray D. Corbett Jr High School | AF15: 8695600 | AH15: Sycamore Creek Apartments | AI15: 63049 | AJ15: =AI15*100 -> 6304900
A16: Sycamore Creek Apartments | C16: =93793*100 -> 9379300 | E16: 5 | G16: =C17/$C$33 -> 0.0033482317 | I16: 9908400 | K16: 4 | R16: Sycamore Creek Apartments | T16: 8581900 | V16: 7 | AA16: Sycamore Creek Apartments | AB16: 87606 | AC16: =AB16*100 -> 8760600 | AE16: Big Time Management | AF16: 8200700 | AH16: Manco Structures | AI16: 62754 | AJ16: =AI16*100 -> 6275400
A17: Comal ISD School | C17: =81215*100 -> 8121500 | E17: 8 | G17: =C17/$C$33 -> 0.0033482317 | R17: Comal ISD | T17: 7150300 | V17: 8 | AA17: Sebastian Apartments | AB17: 66390 | AC17: =AB17*100 -> 6639000 | AE17: Pecan Grove | AF17: 7725100 | AH17: Big Time Management | AI17: 59665 | AJ17: =AI17*100 -> 5966500
A18: Pecan Grove TxLLC | C18: =80721*100 -> 8072100 | E18: 9 | G18: =C18/$C$33 -> 0.0033278657 | I18: 7717900 | K18: 8 | M18: =I18/$I$33 -> 0.004971633 | R18: APG Texas 1LP | T18: 6158400 | V18: 9 | AA18: Legacy Oaks Apartments | AB18: 66172 | AC18: =AB18*100 -> 6617200 | AE18: Val Verde | AF18: 6301600 | AH18: Sysco | AI18: 45540 | AJ18: =AI18*100 -> 4554000
A19: Homestead Residential Master | C19: =77123*100 -> 7712300 | E19: 10 | G19: =C19/$C$33 -> 0.0031795318 | M19: =I19/$I$33 -> 0 | R19: City of Schertz (Soccor Field) | T19: 6095200 | V19: 10 | Z19: 10 | AA19: Republic Beverage Company | AB19: 58243 | AC19: =AB19*100 -> 5824300 | AE19: YMCA/Splash Pad | AF19: 5281200 | AH19: Legacy Oaks Apartments | AI19: 44441 | AJ19: =AI19*100 -> 4444100
A20: Caterpillar Inc | I20: 15705500 | K20: 1 | M20: =I20/$I$33 -> 0.010116999 | R20: SYSCO | AA20: DDC Ashton, LTD | AB20: 48081 | AC20: =AB20*100 -> 4808100 | AH20: City of Schertz(Soccor Field) | AI20: 41964 | AJ20: =AI20*100 -> 4196400
A21: Schertz 1518 | I21: 11373500 | K21: 2 | M21: =I21/$I$33 -> 0.0073264578 | R21: Caterpillar | AA21: Sysco | AB21: 44381 | AC21: =AB21*100 -> 4438100 | AH21: YMCA/Splash Pad | AI21: 40355 | AJ21: =AI21*100 -> 4035500
A22: Beck Readymix | I22: 9916200 | K22: 3 | M22: =I22/$I$33 -> 0.0063877101 | R22: Waterford Ridge Apartments | AA22: Colgate Inc. | AB22: 42092 | AC22: =AB22*100 -> 4209200 | AH22: Sysco | AI22: 35070 | AJ22: =AI22*100 -> 3507000
A23: SYSCO | I23: 8754100 | K23: 5 | M23: =I23/$I$33 -> 0.0056391211 | R23: Beck Readymix | AA23: Silver Tree Nursing Rehab. | AB23: 42031 | AC23: =AB23*100 -> 4203100 | AH23: Wal-Mart Supercenter | AI23: 32557 | AJ23: =AI23*100 -> 3255700
A24: Big Time Management Properties | I24: 8497800 | K24: 6 | M24: =I24/$I$33 -> 0.0054740206 | R24: Ray D. Corbett Jr High School | AA24: IPT San Antonio Logistics | AB24: 487088 | AC24: =AB24*100 -> 48708800 | AH24: Sebastian Apartments | AI24: 31980 | AJ24: =AI24*100 -> 3198000
A25: Sebastian Apartments | I25: 8002100 | K25: 7 | M25: =I25/$I$33 -> 0.0051547059 | R25: Big Time Management
A26: City of Schertz (Ball Park) | I26: 7271400 | K26: 9 | M26: =I26/$I$33 -> 0.0046840115 | R26: Val Verde
A27: Caterpillar Inc | I27: 6426400 | K27: 10 | M27: =I27/$I$33 -> 0.0041396886 | R27: YMCA/Splash Pad
AA28: City of Selma | AC28: =SUMIF($AA$10:$AA$24,AA28,$AC$10:$AC$24) -> 3544002100 | AH28: Lions Fut Ball Club | AJ28: =SUMIF($AH$10:$AH$24,AH28,$AJ$10:$AJ$24) -> 25141000
R29: TOTAL | T29: =SUM(T10:T28) -> 92674100 | AA29: Caterpillar | AC29: =SUMIF($AA$10:$AA$24,AA29,$AC$10:$AC$24) -> 17240100 | AF29: =SUM(AF10:AF28) -> 110104100 | AH29: Sysco | AJ29: =SUMIF($AH$10:$AH$24,AH29,$AJ$10:$AJ$24) -> 18163300
AA30: City of Cibolo | AC30: =SUMIF($AA$10:$AA$24,AA30,$AC$10:$AC$24) -> 14893200 | AH30: Beck Readymix Concrete | AJ30: =SUMIF($AH$10:$AH$24,AH30,$AJ$10:$AJ$24) -> 8567600
A31: TOTAL | C31: =SUM(C12:C30) -> 85121500 | G31: =SUM(G12:G30) -> 0.032662482 | I31: =SUM(I12:I30) -> 93573300 | M31: =SUM(M12:M30) -> 0.053894347 | R31: Total City Water Consumption | T31: ='Table 6#'!T12 -> 0 | AA31: Crossvine Master Community | AC31: =SUMIF($AA$10:$AA$24,AA31,$AC$10:$AC$24) -> 12506100 | AF31: 1552387300 | AH31: Pecan Grove TXLLC | AJ31: =SUMIF($AH$10:$AH$24,AH31,$AJ$10:$AJ$24) -> 6766200
AA32: Pecan Grove TXLLC | AC32: =SUMIF($AA$10:$AA$24,AA32,$AC$10:$AC$24) -> 11073600 | AH32: IPT San Antonio Logistics | AJ32: =SUMIF($AH$10:$AH$24,AH32,$AJ$10:$AJ$24) -> 6447400
A33: Total City Water Consumption | C33: ='Table 6#'!C13 -> 2425608700 | I33: 1552387300 | AA33: Sycamore Creek Apartments | AC33: =SUMIF($AA$10:$AA$24,AA33,$AC$10:$AC$24) -> 8760600 | AH33: Sycamore Creek Apartments | AJ33: =SUMIF($AH$10:$AH$24,AH33,$AJ$10:$AJ$24) -> 6304900
AA34: Sebastian Apartments | AC34: =SUMIF($AA$10:$AA$24,AA34,$AC$10:$AC$24) -> 6639000 | AH34: Manco Structures | AJ34: =SUMIF($AH$10:$AH$24,AH34,$AJ$10:$AJ$24) -> 6275400
AA35: Legacy Oaks Apartments | AC35: =SUMIF($AA$10:$AA$24,AA35,$AC$10:$AC$24) -> 6617200 | AH35: Big Time Management | AJ35: =SUMIF($AH$10:$AH$24,AH35,$AJ$10:$AJ$24) -> 5966500
A36: *Source: Schertz Utility System | AA36: Republic Beverage Company | AC36: =SUMIF($AA$10:$AA$24,AA36,$AC$10:$AC$24) -> 5824300 | AH36: Legacy Oaks Apartments | AJ36: =SUMIF($AH$10:$AH$24,AH36,$AJ$10:$AJ$24) -> 4444100
AA37: DDC Ashton, LTD | AC37: =SUMIF($AA$10:$AA$24,AA37,$AC$10:$AC$24) -> 4808100 | AH37: City of Schertz(Soccor Field) | AJ37: =SUMIF($AH$10:$AH$24,AH37,$AJ$10:$AJ$24) -> 4196400
AA38: Sysco | AC38: =SUMIF($AA$10:$AA$24,AA38,$AC$10:$AC$24) -> 4438100 | AH38: YMCA/Splash Pad | AJ38: =SUMIF($AH$10:$AH$24,AH38,$AJ$10:$AJ$24) -> 4035500

Sheet Table 8
A1: CITY OF SCHERTZ, TEXAS
A3: DIRECT AND OVERLAPPING PROPERTY TAX RATES
A5: LAST TEN FISCAL YEARS
A6: (UNAUDITED)
C9: City Direct Rates | I9: Overlapping School Districts
I10: Schertz-
I11: Cibolo-
A12: Fiscal | C12: Basic | E12: Debt | I12: Universal | K12: Comal
A13: Year | C13: Rate | E13: Service | G13: Total | I13: City ISD | K13: ISD
A14: 2024 | C14: 0.3324 | E14: 0.1548 | G14: 0.4872 | I14: 1.1392 | K14: 1.2746
A15: 2023 | C15: 0.347 | E15: 0.148 | G15: 0.495 | I15: 1.3246 | K15: 1.2746
A16: 2022 | C16: 0.3517 | E16: 0.1604 | G16: =SUM(C16:E16) -> 0.5121 | I16: 1.395 | K16: 1.292
A17: 2021 | C17: 0.347 | E17: 0.1651 | G17: =SUM(C17:E17) -> 0.5121 | I17: 1.4106 | K17: 1.2757
A18: 2020 | C18: 0.3496 | E18: 0.165 | G18: =SUM(C18,E18) -> 0.5146 | I18: 1.42 | K18: 1.32
A19: 2019 | C19: 0.3497 | E19: 0.1649 | G19: =SUM(C19,E19) -> 0.5146 | I19: 1.49 | K19: 1.32
A20: 2018 | C20: 0.3248 | E20: 0.1662 | G20: =SUM(C20:E20) -> 0.491 | I20: 1.49 | K20: 1.39
A21: 2017 | C21: 0.3168 | E21: 0.1743 | G21: =SUM(C21:E21) -> 0.4911 | I21: 1.47 | K21: 1.39
A22: 2016 | C22: 0.3159 | E22: 0.1752 | G22: =SUM(C22:E22) -> 0.4911 | I22: 1.49 | K22: 1.39
A23: 2015 | C23: 0.3164 | E23: 0.181 | G23: =SUM(C23:E23) -> 0.4974 | I23: 1.49 | K23: 1.39
A24: 2014 | C24: 0.301 | E24: 0.1964 | G24: =SUM(C24:E24) -> 0.4974 | I24: 1.49 | K24: 1.43
A25: 2013 | C25: 0.2993 | E25: 0.2006 | G25: =SUM(C25:E25) -> 0.4999 | I25: 1.46 | K25: 1.43
A26: 2012 | C26: 0.2993 | E26: 0.185 | G26: =SUM(C26:E26) -> 0.4843 | I26: 1.435 | K26: 1.43
C28: Overlapping Counties
C29: Bexar
I30: Community
A31: Fiscal | C31: Bexar | E31: Hospital | G31: River | I31: College | K31: Comal | M31: Guadalupe
A32: Year | C32: County | E32: District | G32: Authority | I32: District | K32: County | M32: County
A33: 2024 | C33: 0.276331 | E33: 0.276235 | G33: 0.01836 | I33: 0.14915 | K33: 0.2262 | M33: 0.2731
A34: 2023 | C34: 0.26235 | E34: 0.276235 | G34: 0.01836 | I34: 0.14915 | K34: 0.284715 | M34: 0.3439
A35: 2022 | C35: 0.2763 | E35: 0.2762 | G35: 0.0186 | I35: 0.1492 | K35: 0.314 | M35: 0.3799
A36: 2021 | C36: 0.26235 | E36: 0.276235 | G36: 0.01858 | I36: 0.14915 | K36: 0.322415 | M36: 0.3854
A37: 2020 | C37: 0.277429 | E37: 0.276235 | G37: 0.01858 | I37: 0.14915 | K37: 0.322415 | M37: 0.3319
A38: 2019 | C38: 0.2774 | E38: 0.2762 | G38: 0.0186 | I38: 0.1492 | K38: 0.2952 | M38: 0.3319
A39: 2018 | C39: 0.2928 | E39: 0.276235 | G39: 0.01729 | I39: 0.14915 | K39: 0.307821 | M39: 0.3799
A40: 2017 | C40: 0.2928 | E40: 0.276235 | G40: 0.01729 | I40: 0.14915 | K40: 0.2928 | M40: 0.3851
A41: 2016 | C41: 0.292921 | E41: 0.2762 | G41: 0.01729 | I41: 0.14915 | K41: 0.292921 | M41: 0.3851
A42: 2015 | C42: 0.2929 | E42: 0.276235 | G42: 0.017798 | I42: 0.14915 | K42: 0.2929 | M42: 0.3941
A43: 2014 | C43: 0.278221 | E43: 0.27624 | G43: 0.01737 | I43: 0.14915 | K43: 0.278221 | M43: 0.3999
A44: 2013 | C44: 0.305221 | E44: 0.276235 | G44: 0.01737 | I44: 0.141623 | K44: 0.350421 | M44: 0.4036
A45: 2012 | C45: 0.326866 | E45: 0.276235 | G45: 0.016652 | I45: 0.141623 | K45: 0.334 | M45: 0.4036
...

Sheet Table 9
A1: CITY OF SCHERTZ, TEXAS
A3: PRINCIPAL PROPERTY OF TAX PAYERS
A5: CURRENT YEAR AND NINE YEARS AGO
C9: 2024 | I9: 2015
G10: Percentage | M10: Percentage
G11: of | M11: of
G12: Total City | M12: Total City
C13: Taxable | G13: Taxable | I13: Taxable | M13: Taxable
C14: Assessed | G14: Assessed | I14: Assessed | M14: Assessed
A15: Taxpayer | C15: Value | E15: Rank | G15: Value | I15: Value | K15: Rank | M15: Value
A17: SYSCO Central Texas | C17: =C57 -> 156322530 | E17: 1 | G17: =SUM(C17/C$38) -> 0.023192069 | I17: 100587449 | K17: 2 | M17: =I17/I$38 -> 0.033117743
A18: Sun Life Assurance Company of Canada | C18: =C58 -> 112840728 | E18: 2 | G18: =SUM(C18/C$38) -> 0.016741092
A19: Caterpillar Inc. | C19: =C59 -> 106594902 | E19: 3 | G19: =SUM(C19/C$38) -> 0.015814459 | I19: 157733450 | K19: 1 | M19: =I19/I$38 -> 0.051932681
A20: Amazon Com Services Inc | C20: =C68 -> 80229218 | E20: 4 | G20: =SUM(C20/C$38) -> 0.011902837
A21: Rebublic Beverage Company | C21: =C60 -> 68123480 | E21: 5 | G21: =SUM(C21/C$38) -> 0.010106825 | I21: 48082040 | K21: 3 | M21: =I21/I$38 -> 0.015830689
A22: HGIT Schertz Parkway LP | C22: =C69 -> 61550582 | E22: 6 | G22: =SUM(C22/C$38) -> 0.0091316672
A23: Eastgroup Properties LP | C23: =C61 -> 43686637 | E23: 7 | G23: =SUM(C23/C$38) -> 0.0064813657
A24: WHC Schertz Apts LLC | C24: =C70 -> 35174800 | E24: 8 | G24: =SUM(C24/C$38) -> 0.0052185464
A25: DG Industrial Portfolio II Property Owner LP | C25: =C62 -> 32374472 | E25: 9 | G25: =SUM(C25/C$38) -> 0.0048030887
A26: AR AMZ 1150 Schwab RD LLC | C26: =C63 -> 28910120 | E26: 10 | G26: =SUM(C26/C$38) -> 0.0042891162
A27: San Antonio MTA LP | I27: 23253974 | K27: 4 | M27: =I27/I$38 -> 0.0076562151
A28: GE Oil & Gas Inc. | I28: 19500000 | K28: 5 | M28: =I28/I$38 -> 0.0064202443
A29: Visionary Properties | I29: 18058140 | K29: 6 | M29: =I29/I$38 -> 0.0059455215
A30: Wal-Mart Real Estate Business Trust | I30: 12459300 | K30: 7 | M30: =I30/I$38 -> 0.004102141
A31: H.E.Butt Grocery Co. | I31: 11301240 | K31: 8 | M31: =I31/I$38 -> 0.0037208575
A32: EM Limited Partnership | I32: 9875405 | K32: 9 | M32: =I32/I$38 -> 0.0032514109
A33: Case Cameron LLC | I33: 5878860 | K33: 10 | M33: =I33/I$38 -> 0.0019355752
A35: Totals | C35: =SUM(C17:C34) -> 725807469 | G35: =SUM(G17:G34) -> 0.10768107 | I35: =SUM(I17:I34) -> 406729858 | M35: =SUM(M17:M34) -> 0.13391308
A37: Total Taxable
A38: Assessed Value | C38: ='Table 15'!G10 -> 6740344392 | I38: 3037267611
A40: *Source: Guadalupe, Bexar, and Comal Appraisal Districts
A44: Bexar
A45: Schertz 1518 LTD | C45: 12465260
A46: Pecan Grove TX LLC | C46: 11732490
A47: JEN TEXAS 32 LLC | C47: 7513230
A48: C4LC AT INTERSTATE 10 LLC | C48: 7423140
A49: NAJDS PROPERTY INVESTMENTS INC | C49: 4598940
A50: SA LIBERTY HOME BUILDINGS LLC | C50: 4122500
A51: SCHINDLER ALAN & CAROL TRUST | C51: 3900000
A52: SCOTT FELDER HOMES LLC | C52: 3825951
...

Sheet Table 10
A1: CITY OF SCHERTZ, TEXAS
A3: PROPERTY TAX LEVIES AND COLLECTIONS
A5: LAST TEN FISCAL YEARS
A6: (UNAUDITED)
E9: Collected Within | K9: Total Collections
A10: Fiscal Year | C10: Taxes Levied | E10: Fiscal Year of Levy | I10: Collections In | K10: To Date
A11: Ended | C11: for the | G11: % of | I11: Subsequent | M11: % of
A12: September 30, | C12: Fiscal Year | E12: Amount | G12: Levy | I12: Years | K12: Amount | M12: Levy | T12: 2022 | U12: 2023
A13: 2024 | C13: 28354039 | E13: =28023427.37 -> 28023427 | G13: =SUM(E13/C13) -> 0.98833986 | I13: =SUM(S13:AC13) -> 0 | K13: =I13+E13 -> 28023427 | M13: =SUM(K13/C13) -> 0.98833986
A14: 2023 | C14: 26144518 | E14: 25757953 | G14: =SUM(E14/C14) -> 0.9852143 | I14: =SUM(S14:AC14) -> 57109.9 | K14: =25757953.15+I14 -> 25815063 | M14: =SUM(K14/C14) -> 0.9873987 | U14: 57109.9
A15: 2022 | C15: 22951478 | E15: 22775565 | G15: =SUM(E15/C15) -> 0.99233544 | I15: =SUM(S15:AC15) -> 110107.16 | K15: =E15+I15 -> 22885672 | M15: =SUM(K15/C15) -> 0.99713283 | S15: 0 | T15: 137846.29 | U15: -27739.13
A16: 2021 | C16: 22011090 | E16: 21787625 | G16: =SUM(E16/C16) -> 0.98984762 | I16: =SUM(S16:AC16) -> 24328.5 | K16: =I16+E16 -> 21811954 | M16: =SUM(K16/C16) -> 0.9909529 | S16: 40262 | T16: 1872.83 | U16: -17806.33
A17: 2020 | C17: 20854329 | E17: 20758493 | G17: =SUM(E17/C17) -> 0.9954045 | I17: =SUM(S17:AC17) -> 82648.02 | K17: =I17+E17 -> 20841141 | M17: =SUM(K17/C17) -> 0.99936761 | S17: 68692 | T17: 14934.73 | U17: -978.71
A18: 2019 | C18: 19922568 | E18: 19825244 | G18: =SUM(E18/C18) -> 0.99511489 | I18: =SUM(S18:AC18) -> 91224.06 | K18: =I18+E18 -> 19916468 | M18: =SUM(K18/C18) -> 0.99969382 | S18: 85062 | T18: 2743.18 | U18: 3418.88
A19: 2018 | C19: 18010824 | E19: 17899825 | G19: =SUM(E19/C19) -> 0.99383709 | I19: =SUM(S19:AC19) -> 74731.91 | K19: =I19+E19 -> 17974557 | M19: =SUM(K19/C19) -> 0.99798637 | S19: 71342 | T19: 3206.09 | U19: 183.82
A20: 2017 | C20: 17356822 | E20: 17241556 | G20: =SUM(E20/C20) -> 0.99335904 | I20: =SUM(S20:AC20) -> 74365.98 | K20: 17314231 | M20: =SUM(K20/C20) -> 0.99754615 | S20: 72675 | T20: 1618.83 | U20: 72.15
A21: 2016 | C21: 16238180 | E21: 16160248 | G21: =SUM(E21/C21) -> 0.99520069 | I21: =SUM(S21:AC21) -> 59083.81 | K21: 16218083 | M21: =SUM(K21/C21) -> 0.99876236 | S21: 57835 | T21: 1236.78 | U21: 12.03
A22: 2015 | C22: 14793867 | E22: 14738760 | G22: =SUM(E22/C22) -> 0.99627501 | I22: =SUM(S22:AC22) -> 45621.56 | K22: 14783490 | M22: =SUM(K22/C22) -> 0.99929856 | S22: 44730 | T22: 884.5 | U22: 7.06
A23: 2014 | C23: 13383759 | E23: 13297258 | G23: =SUM(E23/C23) -> 0.99353687 | I23: =SUM(S23:AC23) -> 68805.25 | K23: 13365670 | M23: =SUM(K23/C23) -> 0.99864844 | S23: 68412 | T23: 240.13 | U23: 153.12
A24: 2013 | C24: =5030274+7506266 -> 12536540 | E24: =4997690+7457646 -> 12455336 | G24: =SUM(E24/C24) -> 0.99352261 | I24: =SUM(S24:AC24) -> 71915.3 | K24: 12526768 | M24: =SUM(K24/C24) -> 0.99922052 | S24: 71432 | T24: 477.3 | U24: 6
A25: 2012 | C25: 11239572 | E25: 11159974 | G25: =SUM(E25/C25) -> 0.99291806 | I25: 71740 | K25: 11231714 | M25: =SUM(K25/C25) -> 0.99930086

Sheet Table 11#
A1: CITY OF SCHERTZ, TEXAS
A3: TAXABLE ASSESSED VALUE
A5: LAST TEN FISCAL YEARS
A6: (UNAUDITED)
B8: Fiscal | AC8: Fiscal(Tax)
B9: Year | D9: Taxable | M9: Total Taxable | O9: Total
B10: Ended | D10: Value | F10: Residential | H10: Commercial | I10: Tax-Exempt | K10: Other | M10: Assessed | O10: Direct | R10: 2012 (2011) | AC10: 2014 (2013)
B11: September 30, | D11: January 1, | F11: Property | H11: Property | I11: Property | K11: Property | M11: Value* | O11: Tax Rate | S11: Residential | U11: Commercial | W11: Tax-Exempt | Y11: Other | AA11: Assessed | AD11: Residential | AF11: Commercial | AH11: Tax-Exempt | AJ11: Other | AL11: Assessed
S12: Property | U12: Property | W12: Property | Y12: Property | AA12: Value* | AD12: Property | AF12: Property | AH12: Property | AJ12: Property | AL12: Value*
B13: 2024 | D13: 2023 | F13: =AD96 -> 4664462438 | H13: =AF96 -> 2345387513 | I13: =AH96*-1 -> -386038551 | K13: =AJ96 -> 222037649 | M13: =AL96 -> 7617926151 | O13: 0.4872
B14: 2023 | D14: 2022 | F14: =AD88 -> 4734929478 | H14: =AF88 -> 2047253554 | I14: =AH88 -> -784132143 | K14: =AJ88 -> 742293503 | M14: =AL88 -> 6740344392 | O14: 0.495
B15: 2022 | D15: 2021 | F15: 3618134708 | H15: 1317486482 | I15: -961929765 | K15: 232196469 | M15: =F15+H15+I15+K15 -> 4205887894 | O15: 0.5121
B16: 2021 | D16: 2020 | F16: 3060963760 | H16: 1505592717 | I16: -716028336 | K16: 276109231 | M16: =F16+H16+I16+K16 -> 4126637372 | O16: 0.5121 | R16: Guad | S16: =116135568+1117952496 -> 1234088064 | U16: =188054237+536531032+168345310 -> 892930579 | W16: =AA16-S16-U16-Y16 -> -160834118 | Y16: 39004817 | AA16: 2005189342 | AC16: Guad | AD16: =130610010+1147564056 -> 1278174066 | AF16: =183206281+589856856+188613407 -> 961676544 | AH16: =AL16-AD16-AF16-AJ16 -> -209373502 | AJ16: 37335950 | AL16: 2067813058 | AN16: =AL16-SUM(AD16:AK16) -> 0
B17: 2020 | D17: 2019 | F17: 3004686341 | H17: 1613615732 | I17: -716028336 | K17: 250185870 | M17: =F17+H17+I17+K17 -> 4152459607 | O17: 0.5146 | R17: Comal | S17: =6074570+26783591 -> 32858161 | U17: =74862621+105501299+122695136 -> 303059056 | W17: =AA17-S17-U17-Y17 -> -65740808 | Y17: 42868700 | AA17: 313045109 | AC17: Comal | AD17: =7374840+33472181 -> 40847021 | AF17: =80193586+181154599+269153110 -> 530501295 | AH17: =AL17-AD17-AF17-AJ17 -> -80650703 | AJ17: 46512710 | AL17: 537210323 | AN17: =AL17-SUM(AD17:AK17) -> 0
B18: 2019 | D18: 2018 | F18: 2860333982 | H18: 1401636211 | I18: -621773006 | K18: 260571835 | M18: =F18+H18+I18+K18 -> 3900769022 | O18: 0.5146 | R18: Bexar | S18: =17678093+52599072 -> 70277165 | U18: =28520005+7507078+1670321 -> 37697404 | W18: =AA18-S18-U18-Y18 -> -36016970 | Y18: 21078573 | AA18: 93036172 | AC18: Bexar | AD18: =25184285+101526137 -> 126710422 | AF18: =32491518+11993987+3901851 -> 48387356 | AH18: =AL18-AD18-AF18-AJ18 -> -50723445 | AJ18: 23164860 | AL18: 147539193 | AN18: =AL18-SUM(AD18:AK18) -> 0
B19: 2018 | D19: 2017 | F19: 2049067806 | H19: 2344365139 | I19: -757265921 | K19: 146860809 | M19: =F19+H19+I19+K19 -> 3783027833 | O19: 0.4911 | S19: =SUM(S16:S18) -> 1337223390 | U19: =SUM(U16:U18) -> 1233687039 | W19: =SUM(W16:W18) -> -262591896 | Y19: =SUM(Y16:Y18) -> 102952090 | AA19: =SUM(AA16:AA18) -> 2411270623 | AD19: =SUM(AD16:AD18) -> 1445731509 | AF19: =SUM(AF16:AF18) -> 1540565195 | AH19: =SUM(AH16:AH18) -> -340747650 | AJ19: =SUM(AJ16:AJ18) -> 107013520 | AL19: =SUM(AL16:AL18) -> 2752562574 | AN19: =AL19-SUM(AD19:AK19) -> 0
B20: 2017 | D20: 2016 | F20: 1895085016 | H20: 2269590522 | I20: -649173041 | K20: 132002406 | M20: =F20+H20+I20+K20 -> 3647504903 | O20: 0.4911
B21: 2016 | D21: 2015 | F21: 1702601947 | G21: 0 | H21: 2087223204 | I21: -544328535 | K21: 130353515 | M21: =F21+H21+I21+K21 -> 3375850131 | O21: 0.4974 | R21: 2011 (2010) | AC21: 2015 (2014)
B22: 2015 | D22: 2014 | F22: 1568651309 | H22: 1793803709 | I22: -460271461 | K22: 135084054 | M22: =F22+H22+I22+K22 -> 3037267611 | O22: 0.4974 | S22: Residential | U22: Commercial | W22: Tax-Exempt | Y22: Other | AA22: Assessed | AD22: Residential | AF22: Commercial | AH22: Tax-Exempt | AJ22: Other | AL22: Assessed
B23: 2014 | D23: 2013 | F23: 1445731509 | H23: 1540565195 | I23: -340747650 | K23: 107013520 | M23: =F23+H23+I23+K23 -> 2752562574 | O23: 0.4999 | S23: Property | U23: Property | W23: Property | Y23: Property | AA23: Value* | AD23: Property | AF23: Property | AH23: Property | AJ23: Property | AL23: Value*
B24: 2013 | D24: 2012 | F24: 1383423359 | H24: 1396349905 | I24: -285245142 | K24: 105837429 | M24: =F24+H24+I24+K24 -> 2600365551 | O24: 0.4843 | R24: Guad | S24: =112216195+1086572752 -> 1198788947 | U24: =193120280+551045971+175540268 -> 919706519 | W24: =AA24-S24-U24-Y24 -> -164497836 | Y24: 44631157 | AA24: 1998628787 | AC24: Guad | AD24: =145234340+1209244567 -> 1354478907 | AF24: =199187669+676971846+226949860 -> 1103109375 | AH24: =AL24-AD24-AF24-AJ24 -> -267401494 | AJ24: 40769836 | AL24: 2230956624 | AN24: =AL24-SUM(AD24:AK24) -> 0
R25: Comal | S25: =4921250+24086210 -> 29007460 | U25: =66378691+112773561+124986600 -> 304138852 | W25: =AA25-S25-U25-Y25 -> -82025233 | Y25: 50064050 | AA25: 301185129 | AC25: Comal | AD25: =7263020+41716098 -> 48979118 | AF25: =108640573+179695328+353550967 -> 641886868 | AH25: =AL25-AD25-AF25-AJ25 -> -123240582 | AJ25: 71550262 | AL25: 639175666 | AN25: =AL25-SUM(AD25:AK25) -> 0
G26: 1276925393 | R26: Bexar | S26: =11698414+33475435 -> 45173849 | U26: =23740104+4269761+1745493 -> 29755358 | W26: =AA26-S26-U26-Y26 -> -33491994 | Y26: 22642579 | AA26: 64079792 | AC26: Bexar | AD26: =30089695+135103589 -> 165193284 | AF26: =32417342+12277533+4112591 -> 48807466 | AH26: =AL26-AD26-AF26-AJ26 -> -69629385 | AJ26: 22763956 | AL26: 167135321 | AN26: =AL26-SUM(AD26:AK26) -> 0
B27: *Taxable Assessed Value is before any applicable freeze adjustments. | S27: =SUM(S24:S26) -> 1272970256 | U27: =SUM(U24:U26) -> 1253600729 | W27: =SUM(W24:W26) -> -280015063 | Y27: =SUM(Y24:Y26) -> 117337786 | AA27: =SUM(AA24:AA26) -> 2363893708 | AD27: =SUM(AD24:AD26) -> 1568651309 | AF27: =SUM(AF24:AF26) -> 1793803709 | AH27: =SUM(AH24:AH26) -> -460271461 | AJ27: =SUM(AJ24:AJ26) -> 135084054 | AL27: =SUM(AL24:AL26) -> 3037267611 | AN27: =AL27-SUM(AD27:AK27) -> 0
B29: Source: Bexar, Comal and Guadalupe County Appraisal Districts. | R29: 2010 (2009) | AC29: 2016 (2015)
R30: Guad | S30: =107496843+1060461596 -> 1167958439 | U30: =187944910+536220714+174302549 -> 898468173 | W30: =AA30-S30-U30-Y30 -> -131126359 | Y30: 42630418 | AA30: 1977930671 | AD30: Residential | AF30: Commercial | AH30: Tax-Exempt | AJ30: Other | AL30: Assessed
R31: Comal | S31: =4746720+23227750 -> 27974470 | U31: =68591093+117390628+123564840 -> 309546561 | W31: =AA31-S31-U31-Y31 -> -82039838 | Y31: 51635750 | AA31: 307116943 | AD31: Property | AF31: Property | AH31: Property | AJ31: Property | AL31: Value*
R32: Bexar | S32: =11790735+27226795 -> 39017530 | U32: =22768547+4526922+1974675 -> 29270144 | W32: =AA32-S32-U32-Y32 -> -38051071 | Y32: 27071273 | AA32: 57307876 | AC32: Guad | AD32: =164750611+1266228720 -> 1430979331 | AF32: =198934471+726730743+365045329 -> 1290710543 | AH32: =AL32-AD32-AF32-AJ32 -> -337654740 | AJ32: 36210160 | AL32: 2420245294 | AN32: =AL32-SUM(AD32:AK32) -> 0
S33: =SUM(S30:S32) -> 1234950439 | U33: =SUM(U30:U32) -> 1237284878 | W33: =SUM(W30:W32) -> -251217268 | Y33: =SUM(Y30:Y32) -> 121337441 | AA33: =SUM(AA30:AA32) -> 2342355490 | AC33: Comal | AD33: =7961480+48241271 -> 56202751 | AF33: =109845682+207778984+424384325 -> 742008991 | AH33: =AL33-AD33-AF33-AJ33 -> -131524354 | AJ33: 64735534 | AL33: 731422922 | AN33: =AL33-SUM(AD33:AK33) -> 0
AC34: Bexar | AD34: =42368927+173050938 -> 215419865 | AF34: =35170203+14682970+4650497 -> 54503670 | AH34: =AL34-AD34-AF34-AJ34 -> -75149441 | AJ34: 29407821 | AL34: 224181915 | AN34: =AL34-SUM(AD34:AK34) -> 0
R35: 2009 (2008) | AD35: =SUM(AD32:AD34) -> 1702601947 | AF35: =SUM(AF32:AF34) -> 2087223204 | AH35: =SUM(AH32:AH34) -> -544328535 | AJ35: =SUM(AJ32:AJ34) -> 130353515 | AL35: =SUM(AL32:AL34) -> 3375850131 | AN35: =AL35-SUM(AD35:AK35) -> 0
S36: Residential | U36: Commercial | W36: Tax-Exempt | Y36: Other | AA36: Assessed
S37: Property | U37: Property | W37: Property | Y37: Property | AA37: Value* | AC37: 2017 (2016)
R38: Guad | S38: =97219109+1013854434 -> 1111073543 | U38: =183361564+538651499+172498327 -> 894511390 | W38: =AA38-S38-U38-Y38 -> -136349885 | Y38: 50823659 | AA38: 1920058707 | AD38: Residential | AF38: Commercial | AH38: Tax-Exempt | AJ38: Other | AL38: Assessed
R39: Comal | S39: =4245935+21249143 -> 25495078 | U39: =46023686+124350997+101689180 -> 272063863 | W39: =AA39-S39-U39-Y39 -> -79072186 | Y39: 43714568 | AA39: 262201323 | AD39: Property | AF39: Property | AH39: Property | AJ39: Property | AL39: Value*
R40: Bexar | S40: =10713021+22564227 -> 33277248 | U40: =17692484+4905544+2214060 -> 24812088 | W40: =AA40-S40-U40-Y40 -> -33122511 | Y40: 23598190 | AA40: 48565015 | AC40: Guad | AD40: =173076910+1370700758 -> 1543777668 | AF40: =348181505+778280040+225606648 -> 1352068193 | AH40: =AL40-AD40-AF40-AJ40 -> -44125045 | AJ40: 33060370 | AL40: 2884781186 | AN40: =AL40-SUM(AD40:AK40) -> 0
S41: =SUM(S38:S40) -> 1169845869 | U41: =SUM(U38:U40) -> 1191387341 | W41: =SUM(W38:W40) -> -248544582 | Y41: =SUM(Y38:Y40) -> 118136417 | AA41: =SUM(AA38:AA40) -> 2230825045 | AC41: Comal | AD41: =8554160+57264982 -> 65819142 | AF41: =513309447+232476416+112985684 -> 858771547 | AH41: =AL41-AD41-AF41-AJ41 -> -67170588 | AJ41: 66980133 | AL41: 924400234 | AN41: =AL41-SUM(AD41:AK41) -> 0
AC42: Bexar | AD42: =230632601+54855605 -> 285488206 | AF42: =35393572+16839664+6517546 -> 58750782 | AH42: =AL42-AD42-AF42-AJ42 -> -35233567 | AJ42: 31961903 | AL42: 340967324 | AN42: =AL42-SUM(AD42:AK42) -> 0
R43: 2008 (2007) | AD43: =SUM(AD40:AD42) -> 1895085016 | AF43: =SUM(AF40:AF42) -> 2269590522 | AH43: =SUM(AH40:AH42) -> -146529200 | AJ43: =SUM(AJ40:AJ42) -> 132002406 | AL43: =SUM(AL40:AL42) -> 4150148744 | AN43: =AL43-SUM(AD43:AK43) -> 0
S44: Residential | U44: Commercial | W44: Tax-Exempt | Y44: Other | AA44: Assessed
...

Sheet Table 12
A1: CITY OF SCHERTZ, TEXAS
A3: RATIOS OF OUTSTANDING DEBT BY TYPE
A5: LAST TEN FISCAL YEARS
C10: Governmental Activities | K10: Business-Type Activities | O10: Business-Type Activities
C12: General | E12: Certificates | M12: Certificates | P12: General | V12: Total | X12: Percent
A13: Fiscal | C13: Obligation | E13: of | G13: Tax | I13: Financing | K13: Revenue | M13: of | P13: Obligation | R13: Financing | T13: Tax | V13: Primary | X13: of Gross | Z13: Per
A14: Year | C14: Bonds | E14: Obligation | G14: Notes | I14: Arrangement | K14: Bonds | M14: Obligation | P14: Bonds | R14: Arrangement | T14: Notes | V14: Government | X14: Income | Z14: Capita | AB14: Population
A15: 2024 | C15: 49860745 | E15: 44612349 | G15: 0 | I15: 54614 | K15: 0 | M15: 22590898 | P15: 3263722 | R15: 163843 | T15: 0 | V15: 120546171 | X15: 0.0673 | Z15: =V15/43969 -> 2741.6173 | AB15: 43969
A16: 2023 | C16: =50790000+3714618 -> 54504618 | E16: =24565000+1418440 -> 25983440 | G16: 0 | I16: 81921 | K16: 0 | M16: =22005000+1524237 -> 23529237 | P16: =3525000+562062 -> 4087062 | R16: 245764 | T16: 0 | V16: 108432042 | X16: 0.0582 | Z16: =V16/43010 -> 2521.0891 | AB16: 43010
A17: 2022 | C17: =49375000+5695000+3767302 -> 58837302 | E17: =26135000+1734333 -> 27869333 | G17: 0 | I17: 109228 | K17: 0 | M17: =22845000+1371388 -> 24216388 | P17: =4265000+846592 -> 5111592 | R17: 327685 | T17: 0 | V17: =SUM(C17:T17) -> 116471528 | X17: 0.0524 | Z17: =V17/AB17 -> 2729.375 | AB17: 42673.333
A18: 2021 | C18: 40390000 | E18: 14200000 | G18: 155000 | I18: 136535 | K18: 0 | M18: 10655000 | P18: 2895000 | R18: 475121 | T18: 0 | V18: =SUM(C18:T18) -> 68906656 | X18: 0.0425 | Z18: =V18/AB18 -> 1627.5881 | AB18: 42336.667
A19: 2020 | C19: 44620000 | E19: 15415000 | G19: 345000 | I19: 25695 | K19: 0 | M19: 11200000 | P19: 3685000 | R19: 134662 | T19: 150000 | V19: =SUM(C19:T19) -> 75575357 | X19: 0.045 | Z19: =V19/AB19 -> 1799.4133 | AB19: 42000
A20: 2019 | C20: 48320000 | E20: 16235000 | G20: 530000 | I20: 25699 | K20: 0 | M20: 12330000 | P20: 4445000 | R20: 199421 | T20: 460000 | V20: =SUM(C20:T20) -> 82545120 | X20: 0.056029052 | Z20: 1931.6029
A21: 2018 | C21: 52752896 | E21: 13636966 | G21: 715000 | I21: 34264 | K21: 0 | M21: 13211178 | P21: 2127657 | R21: 289553 | T21: 765000 | V21: =SUM(C21:T21) -> 83532514 | X21: =V21/'Table 17'!E14 -> 0.059816408 | Z21: 2028
A22: 2017 | C22: 56613614 | E22: 9011415 | G22: 1230000 | I22: 25147 | K22: 0 | M22: 8174779 | P22: 2533626 | R22: 92721 | T22: 1065000 | V22: =SUM(C22:T22) -> 78746302 | X22: 0.0622 | Z22: 1996
A23: 2016 | C23: 56352272 | E23: 4057189 | G23: 1740000 | I23: 58321 | K23: 0 | M23: 8331966 | P23: 3014595 | R23: 162262 | T23: 1360000 | V23: =SUM(C23:T23) -> 75076605 | X23: 0.063877628 | Z23: 1979
A24: 2015 | C24: 53410128 | E24: 277801 | G24: 1210000 | I24: 91495 | K24: 0 | M24: 8946153 | P24: 3490564 | R24: 231803 | T24: 1640000 | V24: =SUM(C24:T24) -> 69297944 | X24: 0.059851262 | Z24: 1830
A25: 2014 | C25: 56487433 | E25: 543934 | G25: 1585000 | I25: 123370 | K25: 0 | M25: 9561204 | P25: 3966533 | R25: 347705 | T25: 65000 | V25: =SUM(C25:T25) -> 72680179 | X25: 0.063505763 | Z25: 1992
A26: 2013 | C26: 58693750 | E26: 801767 | G26: 2155000 | I26: 22398 | K26: 2215000 | M26: 5048233 | P26: 2127502 | R26: 0 | T26: 130000 | V26: =SUM(C26:T26) -> 71193650 | X26: 0.064997355 | Z26: 1982
A27: 2012 | C27: 60878759 | E27: 1581300 | G27: 190000 | I27: 60190 | K27: 2342656 | M27: 5383700 | P27: 2413471 | R27: 0 | T27: 190000 | V27: 73040076 | X27: 0.081541676 | Z27: 2117

Sheet Table 13
A1: CITY OF SCHERTZ, TEXAS
A3: RATIOS OF GENERAL BONDED DEBT OUTSTANDING
A5: LAST TEN FISCAL YEARS
C10: General Bonded Debt Outstanding
G11: Less: | K11: Percentage of
C12: General | E12: Certificates | G12: Amounts | K12: Actual Taxable | P12: Taxable Assessed Value
A13: Fiscal | C13: Obligation | E13: of | G13: Available for | K13: Value of | M13: Per | P13: Assessed
A14: Year | C14: Bonds | E14: Obligation | G14: Debt Service | I14: Total | K14: Property | M14: Capita | O14: Population | P14: Value
A15: 2024 | C15: ='Table 12'!P15+'Table 12'!C15 -> 53124467 | E15: ='Table 12'!M15+'Table 12'!E15 -> 67203247 | G15: -1786712 | I15: =C15+E15+G15 -> 118541002 | K15: =I15/'Table 11#'!M13 -> 0.015560797 | M15: =I15/O15 -> 2741.5297 | O15: 43239 | P15: ='Table 11#'!M13 -> 7617926151
A16: 2023 | C16: ='Table 12'!P16+'Table 12'!C16 -> 58591680 | E16: ='Table 12'!M16+'Table 12'!E16 -> 49512677 | G16: -867965 | I16: =C16+E16+G16 -> 107236392 | K16: =I16/'Table 11#'!M14 -> 0.015909631 | M16: =I16/O16 -> 2493.2897 | O16: ='Table 12'!AB16 -> 43010 | P16: ='Table 11#'!M14 -> 6740344392
A17: 2022 | C17: ='Table 12'!C17+'Table 12'!P17 -> 63948894 | E17: ='Table 12'!E17+'Table 12'!M17 -> 52085721 | G17: -1550080 | I17: =C17+E17+G17 -> 114484535 | K17: =I17/'Table 11#'!M15 -> 0.027220063 | M17: =I17/O17 -> 2682.8121 | O17: ='Table 12'!AB17 -> 42673.333 | P17: 4205887894
A18: 2021 | C18: 43285000 | E18: 24855000 | G18: -934899 | I18: =C18+E18+G18 -> 67205101 | K18: =I18/'Table 11#'!M16 -> 0.016285681 | M18: =I18/O18 -> 1587.3971 | O18: ='Table 12'!AB18 -> 42336.667 | P18: 4306840068
A19: 2020 | C19: 46223908 | E19: 15801473 | G19: -1051874 | I19: 60973507 | K19: 0.014683709 | M19: 1480.5863 | O19: ='Table 12'!AB19 -> 42000 | P19: 4152459607
A20: 2019 | C20: 54687960 | E20: 16834029 | G20: -1084908 | I20: 70437081 | K20: 0.018057229 | M20: 1785.3416 | O20: 41948 | P20: 3900769022
A21: 2018 | C21: 54880553 | E21: 13636966 | G21: -809427 | I21: 67708092 | K21: 0.018562852 | M21: 1784.7038 | O21: 41182 | P21: 3647504903
A22: 2017 | C22: 59147240 | E22: 9011415 | G22: -924989 | I22: 67233666 | K22: 0.01991607 | M22: 1775.6151 | O22: 39453 | P22: 3375850131
A23: 2016 | C23: 59366867 | E23: 4057189 | G23: -813306 | I23: 62610750 | K23: 0.02061417 | M23: 1716.4446 | O23: 37938 | P23: 3037267611
A24: 2015 | C24: 56900692 | E24: 277801 | G24: -847178 | I24: 56331315 | K24: 0.020465044 | M24: 1567.8509 | O24: 37865 | P24: 2752562574
A25: 2014 | C25: 60453966 | E25: 543934 | G25: -517199 | I25: 60480701 | K25: 0.023258538 | M25: 1753.1146 | O25: 36477 | P25: 2600365551
A26: 2013 | C26: 60821252 | E26: 801767 | G26: -227674 | I26: 61395345 | K26: 0.025461823 | M26: 1830.2929 | O26: 35929 | P26: 2411270623
A27: 2012 | C27: 63292230 | E27: 1581300 | G27: -117250 | I27: 64756280 | K27: 0.027393905 | M27: 2418.0836 | O27: 34499 | P27: 2363893708

Sheet Table 14
A1: CITY OF SCHERTZ, TEXAS
A3: DIRECT AND OVERLAPPING GOVERNMENTAL ACTIVITIES DEBT
A5: CURRENT YEAR
G7: Estimated
E8: Estimated | G8: Share of
C9: Debt | E9: Percentage | G9: Overlapping
A10: Governmental Unit | C10: Outstanding | E10: Applicable* | G10: Debt
A12: Debt repaid with property taxes:
A14: Alamo CCD | C14: 809962090 | E14: 0.0038 | G14: =C14*E14 -> 3077855.9
A15: Bexar County | C15: 2207225000 | E15: 0.0038 | G15: =C15*E15 -> 8387455
A16: Bexar County Hospital District | C16: 1168200000 | E16: 0.0038 | G16: =C16*E16 -> 4439160
A17: Comal County | C17: 121175000 | E17: 0.0359 | G17: =C17*E17 -> 4350182.5
A18: Comal ISD | C18: 1049362848 | E18: 0.0398 | G18: =C18*E18 -> 41764641
A19: East Central ISD | C19: 101935155 | E19: 0.0334 | G19: =C19*E19 -> 3404634.2
A20: Guadalupe County | C20: 13145000 | E20: 0.1829 | G20: =C20*E20 -> 2404220.5
A21: Judson ISD | C21: 552986085 | E21: 0.0003 | G21: =C21*E21 -> 165895.83
A22: Schertz-Cibolo-Universal ISD | C22: 374839507 | E22: 0.4655 | G22: =C22*E22-0.5 -> 1.7448779e+08
A24: Subtotal, Overlapping Debt | G24: =SUM(G14:G23) -> 2.4248184e+08
A26: City Governmental Activities Direct Debt | G26: 94527708
A28: TOTAL NET OVERLAPPING DEBT | G28: =SUM(G24:G27) -> 3.3700954e+08
A31: NOTES: The overlapping debt was received from the Municipal Advisory Council of Texas. Details regarding the City's outstanding debt can be found in the notes to the basic financial statements.
A33: Overlapping debt is the proportionate share of the debts of local jurisdictions located wholly or in part within the limits of the City of Shertz. This schedule is intended to demonstrate the total debt that the City of Shertz property tax payers will be expected to repay. The amount of debt applicable to the City of Schertz is computed by (a) determining what portion of total assessed value of the overlapping jurisdiction lies within the limits of the City and (b) applying this percentage to the total governmental activities debt of the overlapping jurisdiction.

Sheet Table 15
A1: CITY OF SCHERTZ, TEXAS
A3: DEBT MARGIN INFORMATION
A5: LAST TEN FISCAL YEARS
A10: =CONCATENATE(M10," ",O10," ",Q10) -> Assessed Value, 2023 Tax Roll | G10: ='Table 11#'!M14 -> 6740344392 | M10: Assessed Value, | O10: 2023 | Q10: Tax Roll
A12: Debt Limit - Texas statues do not provide a legal debt limit for cities; however, through accepted practice a practical "economic" debt limit is considered to be 10% of the assessed value. | G12: =(G10*0.1) -> 6.7403444e+08
A17: Amount of Applicable Debt:
A19: General Bonded Debt | E19: ='Table 14'!G26 -> 94527708
A20: Less Debt Service Net Position | E20: ='Table 13'!G16 -> -867965 | G20: =SUM(E19:E20) -> 93659743
A22: DEBT MARGIN | G22: =G12-G20 -> 5.803747e+08
A24: Total Net Debt as a Percentage
A25: of Debt Margin | G25: =SUM(G20/G22) -> 0.16137806
C27: Fiscal Year
C28: 2019 | E28: 2020 | G28: 2021 | I28: 2022
A29: Assessed Value | C29: 3900769022 | E29: 4152459607 | G29: 4070815340 | I29: 6740344392
A31: Debt Limit | C31: =C29/10 -> 3.900769e+08 | E31: =E29/10 -> 4.1524596e+08 | G31: =G29/10 -> 407081534 | I31: 674034439
A32: Total Net Debt Applicable to Limit | C32: 66019954 | E32: 61318507 | G32: 53946636 | I32: 74600814
A33: Total Debt Margin | C33: =SUM(C31-C32) -> 3.2405695e+08 | E33: =SUM(E31-E32) -> 3.5392745e+08 | G33: =SUM(G31-G32) -> 353134898 | I33: =SUM(I31-I32) -> 599433625
C35: 2016 | E35: 2017 | G35: 2018
A36: Assessed Value | C36: 3375850131 | E36: 3647504903 | G36: 3783027833
A38: Debt Limit | C38: =C36/10 -> 3.3758501e+08 | E38: =E36/10 -> 3.6475049e+08 | G38: =G36/10 -> 3.7830278e+08
A39: Total Net Debt Applicable to Limit | C39: 61181169 | E39: 65792916 | G39: 66329699
A40: Total Debt Margin | C40: =SUM(C38-C39) -> 2.7640384e+08 | E40: =SUM(E38-E39) -> 2.9895757e+08 | G40: =SUM(G38-G39) -> 3.1197308e+08
C42: 2013 | E42: 2014 | G42: 2015
A43: Assessed Value | C43: 2600365551 | E43: 2752562574 | G43: 3037267611
A45: Debt Limit | C45: =C43/10 -> 2.6003656e+08 | E45: =E43/10 -> 2.7525626e+08 | G45: =G43/10 -> 3.0372676e+08
A46: Total Net Debt Applicable to Limit | C46: 60499568 | E46: 56803499 | G46: 53424303
A47: Total Debt Margin | C47: =SUM(C45-C46) -> 1.9953699e+08 | E47: =SUM(E45-E46) -> 2.1845276e+08 | G47: =SUM(G45-G46) -> 2.5030246e+08

Sheet Table 16
A1: CITY OF SCHERTZ, TEXAS
A3: PLEDGED REVENUE COVERAGE
A5: LAST TEN FISCAL YEARS
C10: Water Revenue Bonds
C11: Utility | E11: Less: | G11: Net | I11: Debt Service
A12: Fiscal | C12: Service | E12: Operating | G12: Available
A13: Year | C13: Charges | E13: Expenses | G13: Revenue | I13: Principal | K13: Interest | M13: Coverage
A14: 2024 | C14: 32811920 | E14: 31257030 | G14: 1554890 | I14: 1630000 | K14: 967183 | M14: 0.6
A15: 2023 | C15: 31283976 | E15: 29200652 | G15: =C15-E15 -> 2083324 | I15: 1580000 | K15: 1017794.1 | M15: =(G15/(I15+K15)) -> 0.80195885
A16: 2022 | C16: 30876559 | E16: =26921967-2559869 -> 24362098 | G16: =C16-E16 -> 6514461 | I16: 1180000 | K16: 912019 | M16: =(G16/(I16+K16)) -> 3.1139588
A17: 2021 | C17: 28030614 | E17: =24765551-2534305 -> 22231246 | G17: =C17-E17 -> 5799368 | I17: =590000+850000+200000+150000+66953 -> 1856953 | K17: 515413 | M17: =(G17/(I17+K17)) -> 2.4445503
A18: 2020 | C18: 29735911 | E18: 24032772 | G18: =SUM(C18-E18) -> 5703139 | I18: 1961953 | K18: 612643 | M18: =(G18/(I18+K18)) -> 2.2151588
A19: 2019 | C19: 27246250 | E19: =24977492-2354506 -> 22622986 | G19: =SUM(C19-E19) -> 4623264 | I19: 1845132 | K19: 561880 | M19: =(G19/(I19+K19)) -> 1.9207482
A20: 2018 | C20: 27099237 | E20: 20802263 | G20: 6296974 | I20: 1671134 | K20: 391609 | M20: =(G20/(I20+K20)) -> 3.0527186
A21: 2017 | C21: 25390713 | E21: 18697162 | G21: 6693551 | I21: 1554541 | K21: 368390 | M21: 3.48
A22: 2016 | C22: 22003794 | E22: 17603487 | G22: 4400307 | I22: 1441741 | K22: 417346 | M22: =(G22/(I22+K22)) -> 2.3669183
A23: 2015 | C23: 20700369 | E23: 15916597 | G23: =SUM(C23-E23) -> 4783772 | I23: 1448407 | K23: 428912 | M23: =(G23/(I23+K23)) -> 2.5481935
A24: 2014 | C24: 19147872 | E24: 15246653 | G24: =SUM(C24-E24) -> 3901219 | I24: 1010500 | K24: 426100 | M24: =(G24/(I24+K24)) -> 2.7155917
A25: 2013 | C25: 17696327 | E25: 14553274 | G25: =SUM(C25-E25) -> 3143053 | I25: 728800 | K25: 359680 | M25: =(G25/(I25+K25)) -> 2.8875616
A26: 2012 | C26: 17411568 | E26: 14185126 | G26: =SUM(C26-E26) -> 3226442 | I26: 697100 | K26: 396968 | M26: =(G26/(I26+K26)) -> 2.9490324
A29: NOTE: Details regarding the City's outstanding debt can be found in the notes to the basic financial statements. Operating expenses do not include the depreciation, interest, or amortization expenses.

Sheet Table 17
A1: CITY OF SCHERTZ, TEXAS
A3: DEMOGRAPHIC AND ECONOMIC STATISTICS
A5: LAST TEN FISCAL YEARS
A7: Fiscal Year | C7: Population | E7: Personal Income | G7: Per Capita Personal Income | I7: Median Age | K7: Education Level in Years of Schooling | M7: School Enrollment | O7: Unemployment Rate
A8: 2024 | C8: 43239 | E8: 1790872902 | G8: 41418 | I8: 42 | K8: 16 | M8: 15758 | O8: 0.032
A9: 2023 | C9: 43010 | E9: 1734335240 | G9: 40324 | I9: 39 | K9: 15.9 | M9: 15573 | O9: 0.036
A10: 2022 | C10: =(43010-42000)/3+C11 -> 42673.333 | E10: 1.6566641e+09 | G10: 38822 | I10: 37.9 | K10: 15.9 | M10: 15877 | O10: 0.033
A11: 2021 | C11: =(43010-42000)/3+C12 -> 42336.667 | E11: 1.6117146e+09 | G11: 38069 | I11: 37.6 | K11: 16.152302 | M11: 15887 | O11: 0.039
A12: 2020 | C12: 42000 | E12: 1651272000 | G12: 39316 | I12: 37.4 | K12: 16.2 | M12: 15675 | O12: 0.051
A13: 2019 | C13: 41948 | E13: 1473255708 | G13: 35121 | I13: 38 | K13: 16.2 | M13: 15925 | O13: 0.027
A14: 2018 | C14: 41182 | E14: 1396481620 | G14: 33910 | I14: 37.3 | K14: 15.9 | M14: 15817 | O14: 0.032
A15: 2017 | C15: 39453 | E15: 1266046770 | G15: 32090 | I15: 37.2 | K15: 15.9 | M15: 15497 | O15: 0.038
A16: 2016 | C16: 37938 | E16: 1175319240 | G16: 30980 | I16: 36.9 | K16: 15.8 | M16: 15460 | O16: 0.034
A17: 2015 | C17: 37865 | E17: 1157835970 | G17: 30578 | I17: 36.1 | K17: 15.6 | M17: 15009 | O17: 0.032
A18: 2014 | C18: 36477 | E18: 1144465875 | G18: 31375 | I18: 36.9 | K18: 15.4 | M18: 14515 | O18: 0.051
A19: 2013 | C19: 35929 | E19: 1095331494 | G19: 30486 | I19: 37.1 | K19: 15.4 | M19: 14058 | O19: 0.055
A22: Sources: | B22: Population, personal income, median age and education level informaiton provided by City Economic Development Corporation. School enrollment provided by Schertz-Cibolo-Universal City Independent School District. Unemployment data provided by Texas Workforce Commission.
A26: 2005 | C26: 18694 | E26: 593870992 | G26: 31768 | I26: 35.1 | K26: 14.6 | M26: 6186 | O26: 0.039

Sheet Table 18
A1: CITY OF SCHERTZ, TEXAS
A3: TOP TEN PRINCIPAL EMPLOYERS
A5: CURRENT YEAR AND NINE YEARS AGO
D9: 2024 | H9: 2015
A10: Employer | D10: Employees | F10: Percentage of Total City Employment | H10: Employees | J10: Percentage of Total City Employment
A12: Schertz-Cibolo-Universal City ISD | D12: 2032 | F12: =D12/$N$14 -> 0.087034737 | H12: 1810 | J12: 0.1046
A13: Amazon | D13: 800 | F13: =D13/$N$14 -> 0.034265644 | H13: 1073 | J13: 0.062
A14: Sysco Central Texas, Inc | D14: 800 | F14: =D14/$N$14 -> 0.034265644 | H14: 837 | J14: 0.0484 | L14: Total employment in city: | N14: 23347
A15: FedEx Ground - Doerr Lane, Schertz | D15: 650 | F15: =D15/$N$14 -> 0.027840836
A16: Republic National Distributing Company | D16: 600 | F16: =D16/$N$14 -> 0.025699233 | H16: 382 | J16: 0.0221
A17: Brandt Companies | D17: 500 | F17: =D17/$N$14 -> 0.021416028 | H17: 437 | J17: 0.0253
A18: City of Schertz | D18: 480 | F18: =D18/$N$14 -> 0.020559387 | H18: 341 | J18: 0.0197
A19: Visionworks | D19: 403 | F19: =D19/$N$14 -> 0.017261318
A20: Hollingsworth Logistics Group | D20: 400 | F20: =D20/$N$14 -> 0.017132822
A21: H.E.B Grocery Co. | D21: 350 | F21: =D21/$N$14 -> 0.014991219 | H21: 350 | J21: 0.0202
A22: GE Oil & Gas | H22: 600 | J22: 0.0347
A23: Wal-mart Stores | H23: 323 | J23: 0.0187
A24: HVHC | H24: 400 | J24: 0.0231
A26: TOTAL | D26: =SUM(D12:D25) -> 7015 | F26: =SUM(F11:F25) -> 0.30046687 | H26: =SUM(H12:H25) -> 6553 | J26: =SUM(J11:J25) -> 0.3788
A29: Source: City Economic Development Corporation

Sheet Table 19#
A1: CITY OF SCHERTZ, TEXAS
A3: FULL-TIME EQUIVALENT CITY GOVERNMENTAL EMPLOYEES BY FUNCTION
A5: LAST TEN FISCAL YEARS
C8: Full-Time Equivalent Employees as of September 30, | J8: Full-Time Equivalent Employees as of September 30,
A9: Function | C9: 2014 | E9: 2015 | G9: 2016 | I9: 2017 | J9: 2018 | L9: 2019 | N9: 2020 | P9: 2021 | R9: 2022 | T9: 2023 | V9: 2024
A10: General Government
A11: City Manager | C11: 6 | E11: 6 | G11: 5 | I11: 5 | J11: 5 | L11: 5 | N11: 5 | P11: 5 | R11: 5 | T11: 5 | V11: 4
A12: Municipal Court | C12: 6 | E12: 6 | G12: 6 | I12: 6 | J12: 6 | L12: 4 | N12: 4 | P12: 4 | R12: 4 | T12: 4 | V12: 4
A13: Customer Relations | C13: 5 | E13: 5 | G13: 5 | I13: 5 | J13: 5 | L13: 3 | N13: 3 | P13: 3 | R13: 2.5 | T13: 2.5 | V13: 2.5
A14: Planning and Zoning | C14: 3 | E14: 3 | G14: 4 | I14: 4 | J14: 4 | L14: 3 | N14: 3 | P14: 4 | R14: 4 | T14: 4 | V14: 4
A15: General Services | C15: 13 | E15: 13 | G15: 0 | I15: 0 | J15: 0 | L15: 0 | N15: 0 | P15: 0 | R15: 0 | T15: 0 | V15: 0
A16: City Secretary | C16: 2 | E16: 2 | G16: 2 | I16: 2 | J16: 2 | L16: 2 | N16: 2 | P16: 2 | R16: 2 | T16: 2 | V16: 3
A17: Public Affairs | C17: 4 | E17: 4 | G17: 4 | I17: 4 | J17: 5 | L17: 5 | N17: 5 | P17: 4 | R17: 4 | T17: 4 | V17: 3
A18: Records Management | C18: 1 | E18: 1 | G18: 1 | I18: 1 | J18: 0 | L18: 0 | N18: 0 | P18: 0 | R18: 0 | T18: 0 | V18: 0
A19: Schertz Magazine | C19: 2 | E19: 2 | G19: 2 | I19: 2 | J19: 0 | L19: 0 | N19: 0 | P19: 0 | R19: 0 | T19: 0 | V19: 0
A20: Engineer | C20: 3 | E20: 3 | G20: 7 | I20: 7 | J20: 7 | L20: 7 | N20: 8 | P20: 8 | R20: 8 | T20: 10 | V20: 11
A21: GIS | C21: 2 | E21: 2 | G21: 2 | I21: 2 | J21: 2 | L21: 2 | N21: 2 | P21: 2 | R21: 2 | T21: 3 | V21: 3
A22: Information Technology | C22: 6 | E22: 6 | G22: 6 | I22: 7 | J22: 8 | L22: 8 | N22: 8 | P22: 8 | R22: 8 | T22: 9 | V22: 9
... A28: Facility Services | C28: 0 | E28: 0 | G28: 16 | I28: 16 | J28: 17 | L28: 10 | N28: 10 | P28: 11 | R28: 11 | T28: 11 | V28: 11
A29: Public Safety
A30: Police | C30: 75 | E30: 75 | G30: 78 | I30: 81 | J30: 86 | L30: 86 | N30: 87 | P30: 88 | R30: 90 | T30: 94 | V30: 95
A31: Fire | C31: 33 | E31: 33 | G31: 36 | I31: 39 | J31: 45 | L31: 45 | N31: 46 | P31: 46 | R31: 46 | T31: 50 | V31: 53
A32: Inspections | C32: 8 | E32: 9 | G32: 8 | I32: 8 | J32: 11 | L32: 12 | N32: 12 | P32: 12 | R32: 12 | T32: 14 | V32: 14
A33: Marshal Services | C33: 8 | E33: 8 | G33: 8 | I33: 5 | J33: 0 | L33: 0 | N33: 0 | P33: 0 | R33: 0 | T33: 0 | V33: 0
A34: Health
A35: Animal Control | C35: 7 | E35: 7 | G35: 8 | I35: 8 | J35: 7 | L35: 7 | N35: 8 | P35: 9 | R35: 9 | T35: 9 | V35: 9
A36: Environmental Health | C36: 0 | E36: 0 | G36: 3 | I36: 3 | J36: 4 | L36: 4 | N36: 4 | P36: 5 | R36: 5 | T36: 6 | V36: 6
A37: Parks and Culture
A38: Parks | C38: 9 | E38: 9 | G38: 9 | I38: 10 | J38: 12 | L38: 11 | N38: 11 | P38: 11 | R38: 11 | T38: 15 | V38: 16
A39: Pools | C39: 0 | E39: 0 | G39: 0 | I39: 0 | J39: 0 | L39: 0 | N39: 0 | P39: 0 | R39: 0 | T39: 0 | V39: 0
A40: Event Facilities | C40: 1 | E40: 1 | G40: 1 | I40: 1 | J40: 1 | L40: 5 | N40: 5 | P40: 6 | R40: 5.5 | T40: 6.5 | V40: 6.5
A41: Library | C41: =9+4+1 -> 14 | E41: 14 | G41: 14 | I41: 14 | J41: 15 | L41: 14 | N41: 14 | P41: 14 | R41: 14 | T41: 15 | V41: 15
A42: Public Environment
A43: Streets | C43: 14 | E43: 14 | G43: 14 | I43: 14 | J43: 14 | L43: 14 | N43: 17 | P43: 17 | R43: 17 | T43: 17 | V43: 17
A44: Public Works
A45: Public Works | C45: 6 | E45: 6 | G45: 4 | I45: 4 | J45: 4 | L45: 4 | N45: 4 | P45: 4 | R45: 4 | T45: 4 | V45: 4
A46: Business Office | C46: 10 | E46: 10 | G46: 10 | I46: 10 | J46: 10 | L46: 9 | N46: 9 | P46: 9 | R46: 9 | T46: 9 | V46: 10
A47: Water and Sewer | C47: 16 | E47: 16 | G47: 16 | I47: 16 | J47: 19 | L47: 19 | N47: 19 | P47: 21 | R47: 21 | T47: 21 | V47: 21
A48: Drainage | C48: 8 | E48: 8 | G48: 6 | I48: 6 | J48: 8 | L48: 8 | N48: 8 | P48: 8 | R48: 8 | T48: 8 | V48: 8
A49: EMS | C49: 36 | E49: 37 | G49: 39 | I49: 41 | J49: 45 | L49: 45 | N49: 45 | P49: 55 | R49: 55 | T49: 65 | V49: 70
...

Sheet Table 20
A1: CITY OF SCHERTZ, TEXAS
A3: OPERATING INDICATORS BY FUNCTION/PROGRAM
A5: LAST TEN FISCAL YEARS
D9: Fiscal Year | L9: Fiscal Year
A10: Function | D10: 2014 | F10: 2015 | H10: 2016 | K10: 2017 | L10: 2018 | N10: 2019 | P10: 2020 | R10: 2021 | T10: 2022 | V10: 2023 | X10: 2024
A11: General Government
A12: Building Project Permits Issued | D12: 2869 | F12: 3087 | H12: 5919 | K12: 4800 | L12: 5251 | N12: 4748 | P12: 2993 | R12: 4474 | T12: 4000 | V12: 3500 | X12: 4000
A13: Food Establishment Permits | D13: 82 | F13: 135 | H13: 145 | K13: 201 | L13: 181 | N13: 55 | P13: 189 | R13: 159 | T13: 173 | V13: 172 | X13: 189
A14: Food Establishment Inspection | D14: 218 | F14: 136 | H14: 153 | K14: 133 | L14: 211 | N14: 96 | P14: 209 | R14: 192 | T14: 142 | V14: 146 | X14: 237
A15: Foster/Adoption Inspections | D15: 16 | F15: 22 | H15: 21 | K15: 21 | L15: 18 | N15: 8 | P15: 10 | R15: 11 | T15: 5 | V15: 9 | X15: 0
A17: Schertz Magazine
A18: Number of Magazines printed | D18: 180000 | F18: 180000 | H18: 180000 | K18: 180000 | L18: 180000 | N18: 180000 | P18: 187500 | R18: 189700 | T18: 191700 | V18: 192000 | X18: 192000
A20: Police
A21: CFS | D21: 19067 | F21: 36138 | H21: 39064 | K21: 34428 | L21: 45190 | N21: 41327 | P21: 57149 | R21: 29007 | T21: 32170 | V21: 30667 | X21: 32622
A22: Arrests | D22: 686 | F22: 595 | H22: 603 | K22: 423 | L22: 624 | N22: 603 | P22: 527 | R22: 416 | T22: 326 | V22: 355 | X22: 456
A23: Traffic Violations | D23: 15077 | F23: 12306 | H23: 8960 | K23: 8001 | L23: 11359 | N23: 12541 | P23: 8326 | R23: 6980 | T23: 6504 | V23: 5924 | X23: 5159
A24: Accidents | D24: 1823 | F24: 2040 | H24: 2119 | K24: 2057 | L24: 2244 | N24: 2304 | P24: 1752 | R24: 2076 | T24: 2341 | V24: 2085 | X24: 2143
A26: Fire
A27: Number of Rescue/Other Responses | D27: 1759 | F27: 2167 | H27: 2327 | K27: 2758 | L27: 3055 | N27: 3804 | P27: 3953 | R27: 4837 | T27: 4895 | V27: 4994 | X27: 5296
A28: Number of Fire Responses | D28: 110 | F28: 99 | H28: 67 | K28: 86 | L28: 161 | N28: 100 | P28: 108 | R28: 205 | T28: 232 | V28: 182 | X28: 234
A29: Number of Inspections | D29: 252 | F29: 698 | H29: 440 | K29: 519 | L29: 562 | N29: 528 | P29: 500 | R29: 548 | T29: 547 | V29: 674 | X29: 599
A30: Number of Training Classes Conducted | D30: 125 | F30: 150 | H30: 460 | K30: 340 | L30: 600 | N30: 804 | P30: 763 | R30: 770 | T30: 632 | V30: 1032 | X30: 698
A31: Number of Pre-Plan Inspections | D31: 735 | F31: 980 | H31: 867 | K31: 922 | L31: 788 | N31: 865 | P31: 814 | R31: 848 | T31: 324 | V31: 320 | X31: 1007
A33: EMS
A34: Requests for Transport | D34: 8840 | F34: 9286 | H34: 9723 | K34: 9956 | L34: 10059 | N34: 10759 | P34: 10713 | R34: 12251 | T34: 13520 | V34: 14495 | X34: 14997
A35: Actual Transports | D35: 5713 | F35: 6118 | H35: 6123 | K35: 6201 | L35: 6165 | N35: 6738 | P35: 6549 | R35: 7444 | T35: 8332 | V35: 9154 | X35: 9612
A36: EMT Students | D36: 87 | F36: 84 | H36: 89 | K36: 90 | L36: 90 | N36: 90 | P36: 84 | R36: 123 | T36: 154 | V36: 136 | X36: 141
A38: Marshal's Office
A39: Warrants Issues | D39: 2354 | F39: 3798 | H39: 2587 | K39: 2816 | L39: 1598 | N39: 2036 | P39: 1738 | R39: 2095 | T39: 1708 | V39: 1083 | X39: 810
A40: Warrants Cleared | D40: 3781 | F40: 3691 | H40: 3492 | K40: 2822 | L40: 2022 | N40: 1834 | P40: 664 | R40: 1451 | T40: 1373 | V40: 4243 | X40: 877
A42: Parks
A43: Facility Reservations | D43: 301 | F43: 275 | H43: 240 | K43: 251 | L43: 248 | N43: 241 | P43: 75 | R43: 237 | T43: 294 | V43: 334 | X43: 441
A45: Community and Civic Centers
A46: Civic Center Reservations | D46: 458 | F46: 478 | H46: 483 | K46: 590 | L46: 516 | N46: 441 | P46: 293 | R46: 353 | T46: 354 | V46: 416 | X46: 430
A47: Community Center Reservations | D47: 437 | F47: 455 | H47: 370 | K47: 455 | L47: 381 | N47: 326 | P47: 193 | R47: 291 | T47: 299 | V47: 276 | X47: 299
A48: North Community Center Reservations | D48: 244 | F48: 209 | H48: 185 | K48: 230 | L48: 235 | N48: 188 | P48: 92 | R48: 153 | T48: 197 | V48: 196 | X48: 199
A50: Animal Services
A51: Number of Animals Handled | D51: 1218 | F51: 1304 | H51: 1313 | K51: 1283 | L51: 926 | N51: 1157 | P51: 1015 | R51: 1070 | T51: 1125 | V51: 1217 | X51: 1275
A52: Number of Adoptions | D52: 309 | F52: 357 | H52: 410 | K52: 348 | L52: 319 | N52: 366 | P52: 450 | R52: 329 | T52: 371 | V52: 419 | X52: 377
A53: Number of Return to Owners | D53: 222 | F53: 213 | H53: 205 | K53: 228 | L53: 218 | N53: 233 | P53: 335 | R53: 284 | T53: 252 | V53: 279 | X53: 228
...

Sheet Table 21
A1: CITY OF SCHERTZ, TEXAS
A3: CAPITAL ASSET STATISTICS BY FUNCTION/PROGRAM
A5: LAST TEN FISCAL YEARS
C9: Fiscal Year | E9: Fiscal Year | L9: Fiscal Year
A10: Function | C10: 2011 | E10: 2014 | G10: 2015 | I10: 2016 | K10: 2017 | L10: 2018 | N10: 2019 | P10: 2020 | R10: 2021 | T10: 2022 | V10: 2023 | X10: 2024
A11: Police
A12: Stations | C12: 1 | E12: 1 | G12: 1 | I12: 1 | K12: 1 | L12: 1 | N12: 1 | P12: 1 | R12: 1 | T12: 1 | V12: 1 | X12: 1
A13: Police Vehicles | C13: 42 | E13: 42 | G13: 48 | I13: 50 | K13: 64 | L13: 69 | N13: 68 | P13: 72 | R13: 66 | T13: 76 | V13: 90 | X13: 97
A15: Fire
A16: Stations | C16: 2 | E16: 2 | G16: 2 | I16: 2 | K16: 2 | L16: 3 | N16: 3 | P16: 3 | R16: 3 | T16: 3 | V16: 3 | X16: 3
A17: Training Facility | C17: 13 | E17: 0 | G17: 0 | I17: 0 | K17: 0 | L17: 0 | N17: 0 | P17: 0 | R17: 0 | T17: 0 | V17: 0 | X17: 0
A18: Fire Vehicles | E18: 15 | G18: 16 | I18: 16 | K18: 16 | L18: 18 | N18: 19 | P18: 20 | R18: 20 | T18: 24 | V18: 24 | X18: 25
A20: EMS | C20: 6
A21: Ambulances | E21: 7 | G21: 9 | I21: 9 | K21: 8 | L21: 8 | N21: 9 | P21: 9 | R21: 10 | T21: 11 | V21: 12 | X21: 13
A23: Marshal's Office | C23: 8
A24: Vehicles | E24: 7 | G24: 7 | I24: 7 | K24: 7 | L24: 7 | N24: 7 | P24: 7 | R24: 7 | T24: 3 | V24: NA | X24: NA
A26: Streets | C26: 132
A27: Streets, paved (miles) | C27: 5 | E27: 141 | G27: 149.342 | I27: 153 | K27: 159 | L27: 152.6 | N27: 165.4 | P27: 165 | R27: 167.5 | T27: 172.2 | V27: 180 | X27: 182
A28: Streets, unpaved (miles) | E28: 5 | G28: 5 | I28: 5 | K28: 5 | L28: 5 | N28: 5 | P28: 5 | R28: 5 | T28: 5 | V28: 5 | X28: 5
A29: Sidewalks (miles)
C30: 17
A31: Parks and Recreation | C31: 4
A32: Parks - Developed | C32: 15 | E32: 13 | G32: 14 | I32: 15 | K32: 20 | L32: 21 | N32: 21 | P32: 21 | R32: 21 | T32: 21 | V32: 21 | X32: 21
A33: Parks - Undeveloped | C33: 2 | E33: 8 | G33: 9 | I33: 10 | K33: 4 | L33: 4 | N33: 4 | P33: 4 | R33: 5 | T33: 5 | V33: 5 | X33: 5
A34: Playground | C34: 2 | E34: 16 | G34: 18 | I34: 19 | K34: 19 | L34: 19 | N34: 20 | P34: 21 | R34: 21 | T34: 36 | V34: 36 | X34: 36
A35: Swimming Pools | C35: 9 | E35: 2 | G35: 2 | I35: 2 | K35: 4 | L35: 4 | N35: 4 | P35: 4 | R35: 4 | T35: 3 | V35: 3 | X35: 3
A36: Baby Pools | C36: 12 | E36: 2 | G36: 2 | I36: 2 | K36: 2 | L36: 2 | N36: 2 | P36: 2 | R36: 2 | T36: 1 | V36: 1 | X36: 1
A37: Baseball/Softball Diamonds | C37: 4 | E37: 12 | G37: 15 | I37: 15 | K37: 15 | L37: 15 | N37: 15 | P37: 15 | R37: 15 | T37: 15 | V37: 15 | X37: 15
A38: Soccer Fields | E38: 12 | G38: 12 | I38: 12 | K38: 12 | L38: 12 | N38: 12 | P38: 12 | R38: 12 | T38: 12 | V38: 12 | X38: 12
A39: Community Centers | E39: 4 | G39: 4 | I39: 4 | K39: 4 | L39: 4 | N39: 4 | P39: 4 | R39: 4 | T39: 4 | V39: 4 | X39: 4
A40: Splash Pads | C40: 3 | V40: 2 | X40: 2
A42: Animal Services
A43: Control Vehicle | C43: 1 | E43: 3 | G43: 3 | I43: 4 | K43: 3 | L43: 4 | N43: 4 | P43: 6 | R43: 6 | T43: 8 | V43: 8 | X43: 8
C44: 73904
A45: Library
A46: Facility | E46: 1 | G46: 1 | I46: 1 | K46: 1 | L46: 1 | N46: 1 | P46: 1 | R46: 1 | T46: 1 | V46: 1 | X46: 1
A47: Volumes in Collection | C47: 5 | E47: 100478 | G47: 113085 | I47: 97412 | K47: 107382 | L47: 110266 | N47: 150972 | P47: 139447 | R47: 149965 | T47: 155715 | V47: 160533 | X47: 170265
C48: 192
A49: Water
A50: Number of Reservoirs | E50: 0 | G50: 0 | I50: 0 | K50: 0 | L50: 0 | N50: 0 | P50: 0 | R50: 0 | T50: 0 | V50: 0 | X50: 0
...
